Workbook

Sheet Сводка
B3: ФИНАНСОВАЯ МОДЕЛЬ Procter&Gamble
C4: Проект развития digital-маркетинга для категорий Oral Care, Baby Care, Hair Care
B6: КЛЮЧЕВЫЕ ПОКАЗАТЕЛИ ЭФФЕКТИВНОСТИ | G6: Мы разработали стратегию продвижения товаров, учитывая влияние генеративных технологий поиска. Для этого мы проанализировали, как именно формируется поисковая выдача и рекомендации в генеративном поиске, какие запросы реально определяют выбор пользователей и какие платформы оказывают наибольшее влияние на итоговое решение о покупке. Ключевая задача с точки зрения методов ИИ: провести тестирование поисковых срезов в генеративном поиске, чтобы понять, по какому принципу нейросетевые модели (например, лежащие в основе Яндекс.Нейро) отбирают и ранжируют внешние источники. Мы определили и кластеризовали (сгруппировали по типу) индексируемые платформы (обзоры, маркетплейсы, статьи, блоги, экспертные ресурсы), чтобы выявить, каким типам контента нейросети отдают предпочтение при формировании ответа для пользователя. Итогом работы стала построенная финансовая модель с расчетом NPV, IRR, ROI и срока окупаемости.
B8: Показатель | C8: Значение | D8: Описание
B9: NPV проекта | C9: =Метрики_Итог!C6 -> 13198469 | D9: Чистая приведенная стоимость
B10: IRR | C10: =Метрики_Итог!C7 -> 0.56610801 | D10: Внутренняя норма доходности
B11: ROI (5 лет) | C11: =Метрики_Итог!C8 -> 1.1505914 | D11: Возврат инвестиций
B12: Срок окупаемости | C12: =Метрики_Итог!C9 -> 3 | D12: Лет до положительного NPV
B13: ROAS | C13: =Метрики_Итог!C11 -> 5.0682436 | D13: Возврат на затраты рекламы
B16: СТРУКТУРА ФАЙЛА
B18: Лист | C18: Содержание
B19: Допущения | C19: Исходные данные и предпосылки модели
B20: Прогноз_Выручки | C20: Расчет базовой и дополнительной выручки
B21: Затраты | C21: Детализация расходов на продвижение
B22: Денежные_потоки | C22: Расчет EBITDA, FCF, NPV
B23: Метрики_Итог | C23: Сводка KPI для презентации
B26: ПРИМЕЧАНИЯ
B28: • Горизонт планирования: 2026-2030 (5 лет)
B29: ="• Ставка дисконтирования (WACC): "&TEXT(Допущения!C7,"0.0%") -> #VALUE!
B30: ="• Налог на прибыль: "&TEXT(Допущения!C8,"0%") -> • Налог на прибыль: 25%
B31: ="• Курс USD/RUB: "&TEXT(Допущения!C6,"0.00")&" руб." -> #VALUE!
B32: ="• Ramp-up эффекта: "&TEXT(Допущения!C43,"0%")&" → "&TEXT(Допущения!G43,"0%") -> • Ramp-up эффекта: 50% → 100%
B33: Цветовая кодировка:
B34: • Синий шрифт — вводные данные (можно изменять)
B35: • Черный шрифт — расчетные формулы
B36: • Зеленый шрифт — ссылки на другие листы

Sheet Допущения
B3: Таблица 1: Макроэкономические параметры (готово)
B5: Параметр | C5: Значение | D5: Ед. изм. | E5: Источник / Комментарий
B6: Курс USD/RUB | C6: 79.07 | D6: руб. | E6: Средний за 2025-2026
B7: Ставка дисконтирования (WACC) | C7: =0.188 -> 0.188 | D7: % | E7: Ключевая ставка ЦБ 15.5% + риски
B8: Налог на прибыль | C8: 0.25 | D8: % | E8: НК РФ
B9: Горизонт планирования | C9: 5 | D9: лет | E9: 2026-2030
B11: Таблица 2: Рыночные параметры по категориям (готово?)
B13: Параметр | C13: Oral Care | D13: Baby Care | E13: Hair Care | F13: Источник
B14: Объем рынка РФ 2025 (USD) | C14: 1003100000 | D14: 2109082000 | E14: 2366006320 | F14: Оценка на основе доли P&G
B15: Доля P&G на рынке | C15: 0.17 | D15: 0.25 | E15: 0.25 | F15: Nielsen/GfK (допущение)
B16: Выручка P&G базовая (USD) | C16: =C14*C15 -> 170527000 | D16: =D14*D15 -> 527270500 | E16: =E14*E15 -> 591501580 | F16: Расчет
B17: Рост рынка в год | C17: 0.03 | D17: 0.025 | E17: 0.03 | F17: Euromonitor (консервативно)
B18: Валовая маржа P&G | C18: 0.5 | D18: 0.5 | E18: 0.5 | F18: Глобальная 50% минус комиссии МП
B20: Таблица 3: Параметры эффективности продвижения
B22: Параметр | C22: Oral Care | D22: Baby Care | E22: Hair Care | F22: Источник
B23: Рост видимости (Visibility Uplift) | C23: 0.07 | D23: 0.06 | E23: 0.07 | F23: Из анализа пробелов
B24: Эластичность продаж от видимости | C24: 0.5 | D24: 0.5 | E24: 0.5 | F24: Экспертная оценка
B25: Рост продаж (Sales Uplift) | C25: =C23*C24 -> 0.035 | D25: =D23*D24 -> 0.03 | E25: =E23*E24 -> 0.035 | F25: Расчет
B26: Конверсия (CR) | C26: 0.025 | D26: 0.03 | E26: 0.025 | F26: Бенчмарки e-commerce
B27: Средний чек (AOV), USD | C27: 15 | D27: 25 | E27: 12 | F27: Wildberries/Ozon
B28: Cost per Click (CPC), USD | C28: 0.8 | D28: 0.7 | E28: 0.9 | F28: Яндекс.Директ (90 руб/$)
B30: Таблица 4: Стоимость продвижения (рубли и доллары)
B32: Статья расходов | C32: Стоимость (руб) | D32: Стоимость (USD) | E32: Комментарий
B33: Создание экспертной статьи | C33: 50000 | D33: =C33/$C$6 -> 632.35108 | E33: WORKSPACE 2026
B34: SEO-продвижение (мес) | C34: 33000 | D34: =C34/$C$6 -> 417.35171 | E34: Рейтинг Рунета
B35: Размещение у блогера | C35: 30000 | D35: =C35/$C$6 -> 379.41065 | E35: Средний блогер
B36: Размещение на отзовике | C36: 10000 | D36: =C36/$C$6 -> 126.47022 | E36: Irecommend, Otzovik
B37: Технический SEO-аудит | C37: 20000 | D37: =C37/$C$6 -> 252.94043 | E37: Разово
B40: Таблица 5: Коэффициент выхода на эффект (консервативный сценарий)
B42: Год | C42: 2026 | D42: 2027 | E42: 2028 | F42: 2029 | G42: 2030
B43: Коэффициент выхода на эффект | C43: 0.5 | D43: 0.7 | E43: 0.85 | F43: 0.95 | G43: 1

Sheet Прогноз_Выручки
B3: Таблица 1: Базовая выручка (без проекта)
B5: Категория | C5: 2026 | D5: 2027 | E5: 2028 | F5: 2029 | G5: 2030
B6: Oral Care | C6: =Допущения!C16 -> 170527000 | D6: =C6*(1+Допущения!C17) -> 175642810 | E6: =D6*(1+Допущения!C17) -> 1.8091209e+08 | F6: =E6*(1+Допущения!C17) -> 1.8633946e+08 | G6: =F6*(1+Допущения!C17) -> 1.9192964e+08
B7: Baby Care | C7: =Допущения!D16 -> 527270500 | D7: =C7*(1+Допущения!D17) -> 5.4045226e+08 | E7: =D7*(1+Допущения!D17) -> 5.5396357e+08 | F7: =E7*(1+Допущения!D17) -> 5.6781266e+08 | G7: =F7*(1+Допущения!D17) -> 5.8200797e+08
B8: Hair Care | C8: =Допущения!E16 -> 591501580 | D8: =C8*(1+Допущения!E17) -> 6.0924663e+08 | E8: =D8*(1+Допущения!E17) -> 6.2752403e+08 | F8: =E8*(1+Допущения!E17) -> 6.4634975e+08 | G8: =F8*(1+Допущения!E17) -> 6.6574024e+08
B9: ИТОГО базовая | C9: =SUM(C6:C8) -> 1289299080 | D9: =SUM(D6:D8) -> 1.3253417e+09 | E9: =SUM(E6:E8) -> 1.3623997e+09 | F9: =SUM(F6:F8) -> 1.4005019e+09 | G9: =SUM(G6:G8) -> 1.4396779e+09
B12: Таблица 2: Дополнительная выручка (от проекта)
B14: Категория | C14: 2026 | D14: 2027 | E14: 2028 | F14: 2029 | G14: 2030
B15: Oral Care | C15: =C6*Допущения!$C$25*Допущения!C$43 -> 2984222.5 | D15: =D6*Допущения!$C$25*Допущения!D$43 -> 4303248.8 | E15: =E6*Допущения!$C$25*Допущения!E$43 -> 5382134.8 | F15: =F6*Допущения!$C$25*Допущения!F$43 -> 6195786.9 | G15: =G6*Допущения!$C$25*Допущения!G$43 -> 6717537.4
B16: Baby Care | C16: =C7*Допущения!$D$25*Допущения!C$43 -> 7909057.5 | D16: =D7*Допущения!$D$25*Допущения!D$43 -> 11349498 | E16: =E7*Допущения!$D$25*Допущения!E$43 -> 14126071 | F16: =F7*Допущения!$D$25*Допущения!F$43 -> 16182661 | G16: =G7*Допущения!$D$25*Допущения!G$43 -> 17460239
B17: Hair Care | C17: =C8*Допущения!$E$25*Допущения!C$43 -> 10351278 | D17: =D8*Допущения!$E$25*Допущения!D$43 -> 14926542 | E17: =E8*Допущения!$E$25*Допущения!E$43 -> 18668840 | F17: =F8*Допущения!$E$25*Допущения!F$43 -> 21491129 | G17: =G8*Допущения!$E$25*Допущения!G$43 -> 23300908
B18: ИТОГО доп. | C18: =SUM(C15:C17) -> 21244558 | D18: =SUM(D15:D17) -> 30579289 | E18: =SUM(E15:E17) -> 38177046 | F18: =SUM(F15:F17) -> 43869577 | G18: =SUM(G15:G17) -> 47478685
B21: Таблица 3: Общая выручка (базовая + дополнительная)
B23: Категория | C23: 2026 | D23: 2027 | E23: 2028 | F23: 2029 | G23: 2030
B24: Oral Care | C24: =C6+C15 -> 1.7351122e+08 | D24: =D6+D15 -> 1.7994606e+08 | E24: =E6+E15 -> 1.8629423e+08 | F24: =F6+F15 -> 1.9253524e+08 | G24: =G6+G15 -> 1.9864718e+08
B25: Baby Care | C25: =C7+C16 -> 5.3517956e+08 | D25: =D7+D16 -> 5.5180176e+08 | E25: =E7+E16 -> 5.6808964e+08 | F25: =F7+F16 -> 5.8399532e+08 | G25: =G7+G16 -> 5.9946821e+08
B26: Hair Care | C26: =C8+C17 -> 6.0185286e+08 | D26: =D8+D17 -> 6.2417317e+08 | E26: =E8+E17 -> 6.4619287e+08 | F26: =F8+F17 -> 6.6784088e+08 | G26: =G8+G17 -> 6.8904115e+08
B27: ИТОГО общая | C27: =SUM(C24:C26) -> 1.3105436e+09 | D27: =SUM(D24:D26) -> 1.355921e+09 | E27: =SUM(E24:E26) -> 1.4005767e+09 | F27: =SUM(F24:F26) -> 1.4443714e+09 | G27: =SUM(G24:G26) -> 1.4871565e+09
B31: Год | C31: Oral Care | D31: Baby Care | E31: Hair Care
B32: 2026 | C32: =C24 -> 1.7351122e+08 | D32: =C25 -> 5.3517956e+08 | E32: =C26 -> 6.0185286e+08
B33: 2027 | C33: =D24 -> 1.7994606e+08 | D33: =D25 -> 5.5180176e+08 | E33: =D26 -> 6.2417317e+08
B34: 2028 | C34: =E24 -> 1.8629423e+08 | D34: =E25 -> 5.6808964e+08 | E34: =E26 -> 6.4619287e+08
B35: 2029 | C35: =F24 -> 1.9253524e+08 | D35: =F25 -> 5.8399532e+08 | E35: =F26 -> 6.6784088e+08
B36: 2030 | C36: =G24 -> 1.9864718e+08 | D36: =G25 -> 5.9946821e+08 | E36: =G26 -> 6.8904115e+08

Sheet Затраты
B3: Таблица 1: План мероприятий - Oral Care
B5: Мероприятие | C5: Кол-во в 2026 | D5: Цена ед. (USD) | E5: 2026 | F5: 2027 | G5: 2028 | H5: 2029 | I5: 2030
B6: Экспертные статьи | C6: 300 | D6: =Допущения!D33 -> 632.35108 | E6: 300 | F6: 280 | G6: 280 | H6: 260 | I6: 260
B7: SEO-продвижение (мес) | C7: 12 | D7: =Допущения!D34 -> 417.35171 | E7: 12 | F7: 12 | G7: 12 | H7: 12 | I7: 12
B8: Блогеры | C8: 3200 | D8: =Допущения!D35 -> 379.41065 | E8: 3000 | F8: 2800 | G8: 2800 | H8: 2500 | I8: 2300
B9: Размещение на отзовиках | C9: 12000 | D9: =Допущения!D36 -> 126.47022 | E9: 12000 | F9: 12000 | G9: 8000 | H9: 8000 | I9: 6000
B10: Технический SEO-аудит | C10: 1 | D10: =Допущения!D37 -> 252.94043 | E10: 1 | F10: 1 | G10: 1 | H10: 1 | I10: 1
B12: ИТОГО Oral Care | E12: =C6*D6+C7*D7+C8*D8+C9*D9+C10*D10 -> 2926723.2 | F12: =F6*D6+F7*D7+F8*D8+F9*D9+F10*D10 -> 2762311.9 | G12: =G6*D6+G7*D7+G8*D8+G9*D9+G10*D10 -> 2256431 | H12: =H6*D6+H7*D7+H8*D8+H9*D9+H10*D10 -> 2129960.8 | I12: =I6*D6+I7*D7+I8*D8+I9*D9+I10*D10 -> 1801138.2
B15: Таблица 2: План мероприятий - Baby Care
B17: Мероприятие | C17: Кол-во в 2026 | D17: Цена ед. (USD) | E17: 2026 | F17: 2027 | G17: 2028 | H17: 2029 | I17: 2030
B18: Экспертные статьи | C18: 300 | D18: =Допущения!D33 -> 632.35108 | E18: 300 | F18: 280 | G18: 280 | H18: 260 | I18: 260
B19: SEO-продвижение (мес) | C19: 12 | D19: =Допущения!D34 -> 417.35171 | E19: 12 | F19: 12 | G19: 12 | H19: 12 | I19: 12
B20: Блогеры | C20: 3200 | D20: =Допущения!D35 -> 379.41065 | E20: 3200 | F20: 3000 | G20: 2800 | H20: 2500 | I20: 2300
B21: Размещение на отзовиках | C21: 12000 | D21: =Допущения!D36 -> 126.47022 | E21: 12000 | F21: 12000 | G21: 8000 | H21: 8000 | I21: 6000
B22: Технический SEO-аудит | C22: 1 | D22: =Допущения!D37 -> 252.94043 | E22: 1 | F22: 1 | G22: 1 | H22: 1 | I22: 1
B24: ИТОГО Baby Care | E24: =C18*D18+C19*D19+C20*D20+C21*D21+C22*D22 -> 2926723.2 | F24: =F18*D18+F19*D19+F20*D20+F21*D21+F22*D22 -> 2838194 | G24: =G18*D18+G19*D19+G20*D20+G21*D21+G22*D22 -> 2256431 | H24: =H18*D18+H19*D19+H20*D20+H21*D21+H22*D22 -> 2129960.8 | I24: =I18*D18+I19*D19+I20*D20+I21*D21+I22*D22 -> 1801138.2
B27: Таблица 3: План мероприятий - Hair Care
B29: Мероприятие | C29: Кол-во в 2026 | D29: Цена ед. (USD) | E29: 2026 | F29: 2027 | G29: 2028 | H29: 2029 | I29: 2030
B30: Экспертные статьи | C30: 300 | D30: =Допущения!D33 -> 632.35108 | E30: 300 | F30: 280 | G30: 280 | H30: 260 | I30: 260
B31: SEO-продвижение (мес) | C31: 12 | D31: =Допущения!D34 -> 417.35171 | E31: 12 | F31: 12 | G31: 12 | H31: 12 | I31: 12
B32: Блогеры | C32: 3200 | D32: =Допущения!D35 -> 379.41065 | E32: 3000 | F32: 3000 | G32: 2800 | H32: 2500 | I32: 2300
B33: Размещение на отзовиках | C33: 12000 | D33: =Допущения!D36 -> 126.47022 | E33: 12000 | F33: 12000 | G33: 8000 | H33: 8000 | I33: 6000
B34: Технический SEO-аудит | C34: 1 | D34: =Допущения!D37 -> 252.94043 | E34: 1 | F34: 1 | G34: 1 | H34: 1 | I34: 1
B36: ИТОГО Hair Care | E36: =C30*D30+C31*D31+C32*D32+C33*D33+C34*D34 -> 2926723.2 | F36: =F30*D30+F31*D31+F32*D32+F33*D33+F34*D34 -> 2838194 | G36: =G30*D30+G31*D31+G32*D32+G33*D33+G34*D34 -> 2256431 | H36: =H30*D30+H31*D31+H32*D32+H33*D33+H34*D34 -> 2129960.8 | I36: =I30*D30+I31*D31+I32*D32+I33*D33+I34*D34 -> 1801138.2
B39: Сводная таблица затрат по категориям
B41: Категория | C41: 2026 | D41: 2027 | E41: 2028 | F41: 2029 | G41: 2030
B42: Oral Care | C42: =E12 -> 2926723.2 | D42: =F12 -> 2762311.9 | E42: =G12 -> 2256431 | F42: =H12 -> 2129960.8 | G42: =I12 -> 1801138.2
B43: Baby Care | C43: =E24 -> 2926723.2 | D43: =F24 -> 2838194 | E43: =G24 -> 2256431 | F43: =H24 -> 2129960.8 | G43: =I24 -> 1801138.2
B44: Hair Care | C44: =E36 -> 2926723.2 | D44: =F36 -> 2838194 | E44: =G36 -> 2256431 | F44: =H36 -> 2129960.8 | G44: =I36 -> 1801138.2
B45: ИТОГО затраты | C45: =SUM(C42:C44) -> 8780169.5 | D45: =SUM(D42:D44) -> 8438699.9 | E45: =SUM(E42:E44) -> 6769293 | F45: =SUM(F42:F44) -> 6389882.4 | G45: =SUM(G42:G44) -> 5403414.7

Sheet Денежные_потоки
B3: Показатель | C3: 2025 | D3: 2026 | E3: 2027 | F3: 2028 | G3: 2029 | H3: 2030
B5: Доп. выручка | C5: 0 | D5: =Прогноз_Выручки!C18 -> 21244558 | E5: =Прогноз_Выручки!D18 -> 30579289 | F5: =Прогноз_Выручки!E18 -> 38177046 | G5: =Прогноз_Выручки!F18 -> 43869577 | H5: =Прогноз_Выручки!G18 -> 47478685
B6: Переменные затраты | C6: =C5*(1-AVERAGE(Допущения!$C$18:$E$18)) -> 0 | D6: =D5*(1-AVERAGE(Допущения!$C$18:$E$18)) -> 10622279 | E6: =E5*(1-AVERAGE(Допущения!$C$18:$E$18)) -> 15289644 | F6: =F5*(1-AVERAGE(Допущения!$C$18:$E$18)) -> 19088523 | G6: =G5*(1-AVERAGE(Допущения!$C$18:$E$18)) -> 21934788 | H6: =H5*(1-AVERAGE(Допущения!$C$18:$E$18)) -> 23739343
B7: Валовая прибыль (доп.) | C7: =C5-C6 -> 0 | D7: =D5-D6 -> 10622279 | E7: =E5-E6 -> 15289644 | F7: =F5-F6 -> 19088523 | G7: =G5-G6 -> 21934788 | H7: =H5-H6 -> 23739343
B8: Операционные затраты проекта | C8: 0 | D8: =Затраты!C45 -> 8780169.5 | E8: =Затраты!D45 -> 8438699.9 | F8: =Затраты!E45 -> 6769293 | G8: =Затраты!F45 -> 6389882.4 | H8: =Затраты!G45 -> 5403414.7
B9: EBITDA (доп.) | C9: =C7-C8 -> 0 | D9: =D7-D8 -> 1842109.4 | E9: =E7-E8 -> 6850944.5 | F9: =F7-F8 -> 12319230 | G9: =G7-G8 -> 15544906 | H9: =H7-H8 -> 18335928
B10: Налог на прибыль (25%) | C10: =MAX(C9*Допущения!$C$8,0) -> 0 | D10: =MAX(D9*Допущения!$C$8,0) -> 460527.34 | E10: =MAX(E9*Допущения!$C$8,0) -> 1712736.1 | F10: =MAX(F9*Допущения!$C$8,0) -> 3079807.4 | G10: =MAX(G9*Допущения!$C$8,0) -> 3886226.5 | H10: =MAX(H9*Допущения!$C$8,0) -> 4583982
B11: Чистая прибыль (доп.) | C11: =C9-C10 -> 0 | D11: =D9-D10 -> 1381582 | E11: =E9-E10 -> 5138208.4 | F11: =F9-F10 -> 9239422.3 | G11: =G9-G10 -> 11658680 | H11: =H9-H10 -> 13751946
B12: Стартовые инвестиции (pre-launch) | C12: =-Затраты!C45 -> -8780169.5 | D12: 0 | E12: 0 | F12: 0 | G12: 0 | H12: 0
B13: Свободный денежный поток (FCF) | C13: =C11+C12 -> -8780169.5 | D13: =D11+D12 -> 1381582 | E13: =E11+E12 -> 5138208.4 | F13: =F11+F12 -> 9239422.3 | G13: =G11+G12 -> 11658680 | H13: =H11+H12 -> 13751946
B14: Дисконтированный FCF | C14: =C13/(1+Допущения!$C$7)^0 -> -8780169.5 | D14: =D13/(1+Допущения!$C$7)^1 -> 1162947.8 | E14: =E13/(1+Допущения!$C$7)^2 -> 3640649.2 | F14: =F13/(1+Допущения!$C$7)^3 -> 5510557 | G14: =G13/(1+Допущения!$C$7)^4 -> 5853068.4 | H14: =H13/(1+Допущения!$C$7)^5 -> 5811415.8
B15: Нарастающий NPV | C15: =C14 -> -8780169.5 | D15: =C15+D14 -> -7617221.6 | E15: =D15+E14 -> -3976572.5 | F15: =E15+F14 -> 1533984.5 | G15: =F15+G14 -> 7387052.9 | H15: =G15+H14 -> 13198469

Sheet Метрики_Итог
B3: Таблица 1: Основные метрики проекта
B5: Показатель | C5: Значение | D5: Расчет
B6: NPV проекта (USD) | C6: =Денежные_потоки!H15 -> 13198469 | D6: Итоговый NPV за 5 лет
B7: IRR (внутренняя норма доходности) | C7: =IRR(Денежные_потоки!C13:H13) -> 0.56610801 | D7: Встроенная функция Excel IRR
B8: ROI (за 5 лет) | C8: =SUM(Денежные_потоки!D11:H11)/SUM(Денежные_потоки!D8:H8) -> 1.1505914 | D8: Кумулятивная чистая прибыль / кумулятивные OPEX проекта
B9: Срок окупаемости (лет) | C9: =COUNTIF(Денежные_потоки!C15:H15,"<0") -> 3 | D9: Количество лет с отрицательным накопленным NPV
B10: CPA / cost per order - средний (USD) | C10: =SUM(Затраты!C45:G45)/(SUM(Прогноз_Выручки!C15:G15)/Допущения!$C$27+SUM(Прогноз_Выручки!C16:G16)/Допущения!$D$27+SUM(Прогноз_Выручки!C17:G17)/Допущения!$E$27) -> 3.0370832 | D10: Общие затраты / оценка числа новых заказов за 5 лет
B11: ROAS - средний | C11: =SUM(Прогноз_Выручки!C18:G18)/SUM(Затраты!C45:G45) -> 5.0682436 | D11: Суммарная доп. выручка / суммарные OPEX проекта
B12: MIRR | C12: =MIRR(Денежные_потоки!C13:H13,Допущения!$C$7,Допущения!$C$7) -> 0.42730247 | D12: Встроенная функция Excel MIRR
B14: Таблица 2: Показатели по категориям
B16: Категория | C16: Доп. выручка (5 лет) | D16: Затраты (5 лет) | E16: ROI категории
B17: Oral Care | C17: =SUM(Прогноз_Выручки!C15:G15) -> 25582931 | D17: =SUM(Затраты!E12:I12) -> 11876565 | E17: =C17/D17-1 -> 1.1540681
B18: Baby Care | C18: =SUM(Прогноз_Выручки!C16:G16) -> 67027526 | D18: =SUM(Затраты!E24:I24) -> 11952447 | E18: =C18/D18-1 -> 4.6078496
B19: Hair Care | C19: =SUM(Прогноз_Выручки!C17:G17) -> 88738697 | D19: =SUM(Затраты!E36:I36) -> 11952447 | E19: =C19/D19-1 -> 6.424312
B22: Таблица 3: Сводка денежных потоков по годам
B24: Показатель | C24: 2025 | D24: 2026 | E24: 2027 | F24: 2028 | G24: 2029 | H24: 2030 | I24: ИТОГО
B25: Доп. выручка | C25: =Денежные_потоки!C5 -> 0 | D25: =Денежные_потоки!D5 -> 21244558 | E25: =Денежные_потоки!E5 -> 30579289 | F25: =Денежные_потоки!F5 -> 38177046 | G25: =Денежные_потоки!G5 -> 43869577 | H25: =Денежные_потоки!H5 -> 47478685 | I25: =SUM(C25:H25) -> 1.8134915e+08
B26: Затраты на проект | C26: =Денежные_потоки!C8 -> 0 | D26: =Денежные_потоки!D8 -> 8780169.5 | E26: =Денежные_потоки!E8 -> 8438699.9 | F26: =Денежные_потоки!F8 -> 6769293 | G26: =Денежные_потоки!G8 -> 6389882.4 | H26: =Денежные_потоки!H8 -> 5403414.7 | I26: =SUM(C26:H26) -> 35781459
B27: FCF (свободный денежный поток) | C27: =Денежные_потоки!C13 -> -8780169.5 | D27: =Денежные_потоки!D13 -> 1381582 | E27: =Денежные_потоки!E13 -> 5138208.4 | F27: =Денежные_потоки!F13 -> 9239422.3 | G27: =Денежные_потоки!G13 -> 11658680 | H27: =Денежные_потоки!H13 -> 13751946 | I27: =SUM(C27:H27) -> 32389669
B28: Нарастающий NPV | C28: =Денежные_потоки!C15 -> -8780169.5 | D28: =Денежные_потоки!D15 -> -7617221.6 | E28: =Денежные_потоки!E15 -> -3976572.5 | F28: =Денежные_потоки!F15 -> 1533984.5 | G28: =Денежные_потоки!G15 -> 7387052.9 | H28: =Денежные_потоки!H15 -> 13198469

Sheet Графики
A1: График 1: NPV по годам
A2: Год | B2: Нарастающий NPV | C2: Нули
A3: 2025 | B3: =Денежные_потоки!C15 -> -8780169.5 | C3: 0
A4: 2026 | B4: =Денежные_потоки!D15 -> -7617221.6 | C4: 0
A5: 2027 | B5: =Денежные_потоки!E15 -> -3976572.5 | C5: 0
A6: 2028 | B6: =Денежные_потоки!F15 -> 1533984.5 | C6: 0
A7: 2029 | B7: =Денежные_потоки!G15 -> 7387052.9 | C7: 0
A8: 2030 | B8: =Денежные_потоки!H15 -> 13198469 | C8: 0
A22: График 2: Дополнительная выручка vs Затраты
A23: Год | B23: Доп. выручка | C23: Затраты
A24: 2026 | B24: =Прогноз_Выручки!C18 -> 21244558 | C24: =Затраты!C45 -> 8780169.5
A25: 2027 | B25: =Прогноз_Выручки!D18 -> 30579289 | C25: =Затраты!D45 -> 8438699.9
A26: 2028 | B26: =Прогноз_Выручки!E18 -> 38177046 | C26: =Затраты!E45 -> 6769293
A27: 2029 | B27: =Прогноз_Выручки!F18 -> 43869577 | C27: =Затраты!F45 -> 6389882.4
A28: 2030 | B28: =Прогноз_Выручки!G18 -> 47478685 | C28: =Затраты!G45 -> 5403414.7
A42: График 5: Анализ чувствительности
A44: Сценарий | B44: Рост продаж | C44: Ставка дисконтирования | D44: NPV (USD)
A45: Пессимистичный 22% | B45: 0.025 | C45: 0.22 | D45: 2363745
A46: Базовый 19% | B46: =AVERAGE(Допущения!C25:E25) -> 0.033333333 | C46: =Допущения!C7 -> 0.188 | D46: =Метрики_Итог!C6 -> 13198469
A47: Оптимистичный 15% | B47: 0.045 | C47: 0.15 | D47: 31676997

Sheet Анализ
A1: Oral Care | I1: HAIR CARE (Head & Shoulders, Pantene, Herbal Essences, Old Spice) | P1: Baby Care: Pampers
A2: Тип запроса | B2: Запрос | C2: Частота Wordstat (мес) | D2: Топ-3 сайта в поиске | E2: Что говорит Нейро | I2: Тип запроса | J2: Запрос | K2: Частота Wordstat (мес) | L2: Топ-3 сайта в поиске | M2: Что говорит Нейро | P2: Тип запроса | Q2: Запрос | R2: Частота Wordstat (мес) | S2: Топ-3 сайта в поиске | T2: Что говорит Нейро
A3: Брендовые | B3: Oral-B | C3: 59599 | D3: goldapple.ru (промо), | E3: купить doctorslon.ru, oralb-russia.ru | I3: Категорийный | J3: шампунь от перхоти | K3: 106214 | L3: goldapple.ru (промо), | M3: Некоторые шампуни от перхоти: | P3: Категорийный | Q3: подгузники | R3: 262344 | S3: market.yandex.ru(промо), | T3: lenta.com. Предлагает подгузники брендов 365 ДНЕЙ, HUGGIES, JOONIES, LITTLE TIMES, MEPSI, MERRIES, PAMPERS, TANOSHI, YASASHII, YOKOSUN.
D4: ozon.ru (промо), | L4: ozon.ru (промо), | M4: 2в1 Clear Men «Глубокое очищение»… | S4: wildberries.ru
D5: oralb-russia.ru (промо), | L5: yves-rocher.ru (промо) | M5: Head & Shoulders 2в1 Classic Clean… | S5: ozon.ru (промо),
B6: Орал би | C6: 25863 | D6: braun-russia.ru, | E6: irrigator.ru, oralb-russia.ru | L6: apteka.ru, | M6: Vichy Dercos Anti‑Dandruff… | S6: detmir.ru,
D7: ozon.ru, doctorslon.ru | L7: Вебмастер (15 116) | M7: «Низорал»… | S7: Вебмастер (15 116)
B8: Oral-B зубная щетка отзывы | C8: 612 | L8: (https://wildberries.ru | M8: «Кето Плюс»… | S8: (https://wildberries.ru
B9: Oral-B электрическая зубная щетка | C9: 14719 | D9: market.yandex.ru, ozon.ru, mvideo.ru | E9: Купить apteka.ru, doctorslon.ru, irrigator.ru | L9: https://ozon.ru | M9: «Циновит»… | S9: https://ozon.ru
B10: Орал би электрическая зубная щетка | C10: 4473 | D10: market.yandex.ru, ozon.ru, topsmile.shop | E10: doctorslon.ru, apteka.ru, ozon.ru, market.yandex.ru | L10: https://apteka.ru) | M10: «Себозол»… | S10: https://apteka.ru)
B11: Oral-B зубная нить | C11: 1047 | J11: шампунь против перхоти | K11: 22713 | L11: goldapple.ru (промо), | M11: Некоторые шампуни против перхоти: | Q11: детские подгузники | R11: 8338 | S11: market.yandex.ru | T11: Детские подгузники различаются по нескольким критериям: вес и возраст ребёнка, пол, назначение и способ крепления. uteka.ru
B12: Blend-a-med | C12: 1514 | L12: ozon.ru (промо), | M12: «Низорал». | S12: detmir.ru | T12: Некоторые бренды и модели:
B13: Блендамед | C13: 2960 | D13: apteka.ru, ozon.ru, megapteka.ru | E13: wikipedia.org, megapteka.ru, ozon.ru, market.yandex.ru | L13: yves-rocher.ru (промо) | M13: «Кето Плюс». | S13: ozon.ru | T13: Pampers Premium Care. Есть варианты для детей весом 0 (до 3 кг), 1 (2–5 кг) и 2 (4–8 кг). uteka.ru
B14: Blend-a-med зубная паста | C14: 1064 | L14: apteka.ru, | M14: «Циновит». | S14: wildberries.ru | T14: Huggies Elite Soft. Выпускаются для детей весом 0 (до 3,5 кг) и 1 (3–5 кг). uteka.ru
A15: Категорийные | B15: электрическая зубная щетка | C15: 92355 | D15: market.yandex.ru, ozon.ru, top-advisorr.ru | E15: wikipedia.org упоминается в категориях щеток, | L15: Вебмастер (1 550) | M15: Vichy Dercos. | S15: apteka.ru | T15: Huggies Dry Expert. Одноразовые подгузники-трусики для детей весом 12–17 кг, размер 5. uteka.ru
E16: megapteka.ru Сравнение электрических и мануальных щеток для зубов, | L16: (https://apteka-april.ru | M16: Mirrolla Сульсен Форте. | T16: Junion Comfy. Есть подгузники на липучках для детей весом 3–8 кг (размер Newborn-S) и 6–11 кг (размер M).
E17: realty.yandex.ru как выбрать электрическую зубную щётку | L17: https://market.yandex.ru | M17: Ducray Kelual DS.
E18: doctorslon.ru | L18: https://stolichki.ru) | M18: Сульсена (Амальгама Люкс). | P18: Брендовые | Q18: памперс | R18: 308295 | S18: market.yandex.ru (промо), | T18: Pampers (Памперс) — торговая марка, под которой выпускаются подгузники, подгузники-трусики для детей и влажные салфетки. Бренд принадлежит компании Procter and Gamble.
E19: entomirshop.ru | M19: «Псорилом». | S19: detmir.ru (промо),
B20: зубная щетка | C20: 342391 | D20: market.yandex.ru на запрос сразу предлагает электрические щетки среди которых есть мы | M20: Bioderma Node DS+. | S20: ozon.ru (промо),
B21: лучшая электрическая зубная щетка | C21: 9487 | D21: рейтинги-товаров.рфпромо, bwell, ozon.ru | E21: Нельзя однозначно сказать, какая электрическая зубная щётка лучшая — выбор зависит от индивидуальных потребностей и особенностей зубов и дёсен. Существуют разные типы щёток: звуковые, ультразвуковые и механические. | J21: шампунь для перхоти | K21: 19756 | L21: goldapple.ru (промо), | M21: Некоторые шампуни от перхоти: | S21: apteka.ru
E22: В механических мы всегда есть | L22: ozon.ru (промо), | M22: «Низорал». | S22: wildberries.ru
E23: Статьи expertcen.ru , dtf.ru, | L23: apteka.ru | M23: «Кето Плюс». | Q23: pampers | R23: 8588 | S23: market.yandex.ru (промо), | T23: Pampers (рус. «Памперс») — торговая марка компании Procter & Gamble, выпускающая подгузники и детские влажные салфетки. ru.wikipedia.org*
E24: Купить megapteka.ru | M24: «Циновит». | S24: detmir.ru (промо),
E25: Промо: статьи рейтинги-товаров.рф, top-advisorr.ru | M25: Vichy Dercos. | S25: pampers.com
B26: зубная щетка электрическая какую выбрать | C26: 1786 | M26: «Сульсен Форте». | P26: Консультационные | Q26: какие подгузники лучше | R26: 2935 | S26: market.yandex.ru (промо), | T26: Некоторые бренды подгузников, которые отмечают как подходящие:
B27: зубная нить | C27: 33658 | D27: market.yandex.ru, ozon.ru, wildberries.ru | E27: Без брендов ничего нет, только в начале купить на market.yandex.ru, , Если добавлять бренд, то появляется статьи medalist-stom.ru, health.mail.ru | M27: Ducray Kelual DS. | S27: detmir.ru (промо), | T27: Merries. Японский бренд премиум-класса с воздухопроницаемым материалом и мягкой текстурой. Отличается надёжной защитой от протеканий и гипоаллергенным составом.
A28: Сравнительные | B28: Oral-B или | C28: 873 | D28: купить oral-b ozon.ru, goldapple.ru (промо) | M28: «Псорилом». | S28: ozon.ru ( | T28: YokoSun. Японские подгузники с индикатором наполнения и анатомической формой. Имеют хорошую впитываемость и эластичные боковинки.
B29: электрическая или обычная зубная щетка | C29: 687 | D29: ozon.ru (промо), market.yandex.ru | J29: лучший шампунь от перхоти | K29: 10037 | L29: goldapple.ru (промо), | M29: Нет однозначного мнения о том, какой шампунь от перхоти лучший. Несколько средств, которые упоминаются в рейтингах 2026 года: | T29: Huggies. Американский бренд с широкой линейкой продукции. Трусики имеют удобные застёжки-липучки для лёгкой смены.
A30: Консультационные | B30: как выбрать электрическую зубную щетку | C30: 1097 | D30: (Промо) top-advisorr.ru, | L30: market.yandex.ru (промо), | M30: 2в1 Clear Men «Глубокое очищение». | T30: KIOSHI. Японские подгузники с усиленным впитывающим слоем. Особенность — мягкие манжеты вокруг ножек, предотвращающие натирание.
D31: рейтинги-товаров.рф, ozon.ru, | L31: stolichki.ru | M31: Head & Shoulders 2в1 Classic Clean. | T31: Junion Flexy. Ультратонкие трусики по японской технологии. Внутренний слой — мягкие 3D-подушечки, которые не должны натирать, и анатомическая посадка 360° и ультрамягкий эластичный пояс.
D32: (Купить) doctorslon.ru, market.yandex.ru, goldapple.ru | L32: megapteka.ru | M32: «Низорал» (с кетоконазолом 1%). | T32: vc.ru
B33: как чистить зубы электрической щеткой | C33: 1949 | D33: Топ электрических щеток (промо) revizzoro.ru | E33: ichip.ru, OZON.ru, novadent.ru, dentalab.ru | L33: Вебмастер (466) | M33: LA Roche‑Posay Kerium Интенсивный. | Q33: какие памперсы лучше | R33: 1837 | S33: market.yandex.ru (промо), | T33: Некоторые модели, которые отмечают как подходящие:
L34: (https://lamoda.ru ??? | M34: Yones с кетоконазолом 2%. | S34: detmir.ru (промо), | T34: Huggies Elite Soft — подгузники с двумя зонами впитывания — передняя часть поглощает жидкость, а задняя впитывает жидкий стул.
L35: https://stolichki.ru | S35: ozon.ru ( | T35: Pampers Premium Care — подгузники с индикатором заполняемости и вырезом под пупок.
L36: https://megapteka.ru) | T36: Junion Flexy — тонкие подгузники с технологией Flex Absorb, которые не сковывают движений и имеют высокие двойные бортики для защиты от протечек.
J37: шампунь для жирных волос | K37: 18863 | L37: market.yandex.ru (промо), | M37: Несколько шампуней для жирных волос: | T37: deti.mail.rumarket.yandex.ru
L38: goldapple.ru (промо), | M38: L'Oreal Paris Elseve «Гиалурон Баланс». Шампунь для волос | Q38: какие подгузники | R38: 10915 | S38: market.yandex.ru (промо), | T38: Некоторые популярные бренды одноразовых подгузников:
L39: wildberries.ru (промо), | M39: Deonica Detox Очищение. | S39: detmir.ru (промо), | T39: Pampers — предлагает разные линейки продуктов, например, серию Pampers Premium Care с вырезами для пупка, эластичными боковинками и индикатором влаги.
L40: ozon.ru (промо), | M40: Green Mama «Биобаланс» с экстрактом ламинарии. | S40: ozon.ru ( | T40: Huggies — есть линейки для мальчиков и девочек, ночные подгузники и модели для детей более старшего возраста. Например, серия Huggies Elite Soft с двойными бортиками, кармашками для протекания и зонированием внутри подгузника для разного отделяемого.
...
